1).package exception.com.tech.palle;

public class Exception {

	public static void main(String[] args) {
		System.out.println("sahana");
		int i =10;
		try{
		i = i/0;	
			System.out.println("hi");
		}
        catch(ArithmeticException e) {
			System.out.println("banglore");
		}
		System.out.println(i);
        
	}
}
2).package exception.com.tech.palle;

public class Exception1 {

	public static void main(String[] args) {
		try {
			try {
				System.out.println(10/0);
			}
		   catch(ArithmeticException e) {
			   System.out.println("hi");
		   }
		}
		catch(ArithmeticException e) {
			System.out.println("banglore");
		}
		finally {
			System.out.println("sahana");
		}
	}
}
3).package exception.com.tech.palle;

public class Exception2 {

	public static void main(String[] args) {
		try {
			System.out.println(10/5);
			try {
				System.out.println(10/0);
			}
		   catch(ArrayIndexOutOfBoundsException e) {
			   System.out.println("hi");
		   }
		}
		catch(ArithmeticException ex) {
			System.out.println("banglore");
		}
		finally {
			System.out.println("sahana");
		}
	}
}

11/09/2024
package exception.com.tech.palle;

public class Exception3 {

    public static void main(String[] args) {
        System.out.println("welcome");

        // First try-catch block to handle ArithmeticException
        try {
            int i = 20 / 0;  // This will throw ArithmeticException
        } catch (ArithmeticException e) {
            System.out.println("sahana");
        }

        // Second try-catch block to handle ArrayIndexOutOfBoundsException
        try {
            int[] a = {1, 2, 3};
            System.out.println(a[3]);  // This will throw ArrayIndexOutOfBoundsException
        } catch (ArrayIndexOutOfBoundsException e) {
            System.out.println("array");
        }

        // Finally block that always executes
        finally {
            System.out.println("mm");
        }
    }
}
 here we can handle bot the exception easily
****************but here**************
package exception.com.tech.palle;

public class Exception3 {

    public static void main(String[] args) {
        System.out.println("welcome");

        try {
            int i = 20 / 0;  // First exception
            try {
                int[] a = {1, 2, 3};
                System.out.println(a[3]);  // Second exception
            } catch (ArrayIndexOutOfBoundsException e) {
                System.out.println("array");
            }
        } catch (ArithmeticException e) {
            System.out.println("sahana");
        } finally {
            System.out.println("mm");
        }
    }
}
here we can handle the ArrayIndexOutOfBoundsException but cant get the output
